<?xml version="1.0" ?>
<!-- =================================================================================== -->
<!-- |    This document was autogenerated by xacro from manipulator.xacro              | -->
<!-- |    EDITING THIS FILE BY HAND IS NOT RECOMMENDED                                 | -->
<!-- =================================================================================== -->
<robot name="3R">
  <link name="base_link">
    <visual>
      <origin rpy="0 0 0" xyz="0 0 0"/>
      <geometry>
        <box size="1 1 1"/>
      </geometry>
    </visual>
    <inertial>
      <origin rpy="0.0 0.0 0.0" xyz="0.0 0.0 0.0"/>
      <mass value="1024"/>
      <inertia ixx="170.667" ixy="0.0" ixz="0.0" iyy="170.667" iyz="0.0" izz="170.667"/>
    </inertial>
    <collision>
      <origin rpy="0.0 0.0 0.0" xyz="0.0 0.0 0.0"/>
      <geometry>
        <box size="1 1 1"/>
      </geometry>
    </collision>
  </link>
  <joint name="base_link_link_01" type="revolute">
    <origin rpy="0 0 0" xyz="0 0 0.5"/>
    <parent link="base_link"/>
    <child link="link_01"/>
    <axis xyz="0 0 1"/>
    <limit effort="1000.0" lower="-3.14" upper="3.14" velocity="0.5"/>
  </joint>
  <link name="link_01">
    <visual>
      <origin rpy="0 0 0" xyz="0 0 0.2"/>
      <geometry>
        <cylinder length="0.4" radius="0.35"/>
      </geometry>
    </visual>
    <inertial>
      <origin rpy="0 0 0" xyz="0 0 0.2"/>
      <mass value="1.5633"/>
      <inertia ixx="0.16447" ixy="0" ixz="0" iyy="0.16447" iyz="0" izz="0.0957"/>
    </inertial>
    <collision>
      <origin rpy="0 0 0" xyz="0 0 0.2"/>
      <geometry>
        <cylinder length="0.4" radius="0.35"/>
      </geometry>
    </collision>
  </link>
  <joint name="link_01_link_02" type="revolute">
    <origin rpy="0 0 0" xyz="0 0 0.4"/>
    <parent link="link_01"/>
    <child link="link_02"/>
    <axis xyz="0 1 0"/>
    <limit effort="1000.0" lower="-3.14" upper="3.14" velocity="0.5"/>
  </joint>
  <link name="link_02">
    <visual>
      <origin rpy="0 0 0" xyz="0 0 0.4"/>
      <geometry>
        <cylinder length="0.8" radius="0.15"/>
      </geometry>
    </visual>
    <inertial>
      <origin rpy="0 0 0" xyz="0 0 0.4"/>
      <mass value="1.0986"/>
      <inertia ixx="0.06168" ixy="0.0" ixz="0.0" iyy="0.06168" iyz="0.0" izz="0.0126"/>
    </inertial>
    <collision>
      <origin rpy="0 0 0" xyz="0 0 0.4"/>
      <geometry>
        <cylinder length="0.8" radius="0.15"/>
      </geometry>
    </collision>
  </link>
  <joint name="link_02_link_03" type="revolute">
    <origin rpy="0 0 0" xyz="0 0 0.8"/>
    <parent link="link_02"/>
    <child link="link_03"/>
    <axis xyz="0 1 0"/>
    <limit effort="1000.0" lower="-3.14" upper="3.14" velocity="0.5"/>
  </joint>
  <link name="link_03">
    <visual>
      <origin rpy="0 0 0" xyz="0 0 0.4"/>
      <geometry>
        <cylinder length="0.8" radius="0.15"/>
      </geometry>
    </visual>
    <inertial>
      <origin rpy="0 0 0" xyz="0 0 0.4"/>
      <mass value="1.0986"/>
      <inertia ixx="0.06168" ixy="0.0" ixz="0.0" iyy="0.06168" iyz="0.0" izz="0.0126"/>
    </inertial>
    <collision>
      <origin rpy="0 0 0" xyz="0 0 0.4"/>
      <geometry>
        <cylinder length="0.8" radius="0.15"/>
      </geometry>
    </collision>
  </link>
  <!-- <xacro:m_joint name="link_03_link_04" type="revolute" axis_xyz="0 0 1" origin_rpy="0 0 0" origin_xyz="0 0 0.8" parent="link_03" child="link_04"/> -->
  <!-- <xacro:m_link_cylinder name="link_04" origin_rpy="0 0 0" origin_xyz="0 0 0.4" radius="0.15" length="0.8" mass="1.0986" ixx="0.06168" ixy="0.0" ixz="0.0" iyy="0.06168" iyz="0.0" izz="0.0126"/> -->
  <gazebo>
    <plugin filename="libmotor_plugin.dylib" name="motor_control">
        </plugin>
  </gazebo>
  <gazebo>
    <plugin filename="libgazebo_ros_joint_state_publisher.so" name="joint_state_publisher">
      <jointName>base_link_link_01</jointName>
      <!-- <jointName>link_01_link_02</jointName> -->
      <updateRate>50.0</updateRate>
      <alwaysOn>True</alwaysOn>
    </plugin>
    <plugin filename="libgazebo_ros_joint_state_publisher.so" name="joint_state_publisher">
      <!-- <jointName>base_link_link_01</jointName> -->
      <jointName>link_01_link_02</jointName>
      <updateRate>50.0</updateRate>
      <alwaysOn>True</alwaysOn>
    </plugin>
    <plugin filename="libgazebo_ros_joint_state_publisher.so" name="joint_state_publisher">
      <!-- <jointName>base_link_link_01</jointName> -->
      <jointName>link_02_link_03</jointName>
      <updateRate>50.0</updateRate>
      <alwaysOn>True</alwaysOn>
    </plugin>
  </gazebo>
</robot>

